Traceback (most recent call last):
  File "C:\Users\User\AppData\Local\Programs\Python\Python39\lib\site-packages\jupyter_cache\executors\utils.py", line 51, in single_nb_execution
    executenb(
  File "C:\Users\User\AppData\Local\Programs\Python\Python39\lib\site-packages\nbclient\client.py", line 1117, in execute
    return NotebookClient(nb=nb, resources=resources, km=km, **kwargs).execute()
  File "C:\Users\User\AppData\Local\Programs\Python\Python39\lib\site-packages\nbclient\util.py", line 78, in wrapped
    return just_run(coro(*args, **kwargs))
  File "C:\Users\User\AppData\Local\Programs\Python\Python39\lib\site-packages\nbclient\util.py", line 57, in just_run
    return loop.run_until_complete(coro)
  File "C:\Users\User\AppData\Local\Programs\Python\Python39\lib\asyncio\base_events.py", line 642, in run_until_complete
    return future.result()
  File "C:\Users\User\AppData\Local\Programs\Python\Python39\lib\site-packages\nbclient\client.py", line 558, in async_execute
    await self.async_execute_cell(
  File "C:\Users\User\AppData\Local\Programs\Python\Python39\lib\site-packages\nbclient\client.py", line 862, in async_execute_cell
    self._check_raise_for_error(cell, exec_reply)
  File "C:\Users\User\AppData\Local\Programs\Python\Python39\lib\site-packages\nbclient\client.py", line 765, in _check_raise_for_error
    raise CellExecutionError.from_cell_and_msg(cell, exec_reply_content)
nbclient.exceptions.CellExecutionError: An error occurred while executing the following cell:
------------------
import pandas as pd
import numpy as np
from matplotlib import pyplot as plt
from pathlib import Path
import seaborn as sns
import xlwings as xw
import researchtools.api as rt
plt.style.use('ggplot')
plt.rcParams['figure.figsize'] = [14, 8]

from typing import List, Dict, Tuple, Optional, Union, Callable, Any, Iterable

------------------

[1;31m---------------------------------------------------------------------------[0m
[1;31mModuleNotFoundError[0m                       Traceback (most recent call last)
[1;32m~\AppData\Local\Temp\ipykernel_1192\3475486766.py[0m in [0;36m<module>[1;34m[0m
[0;32m      5[0m [1;32mimport[0m [0mseaborn[0m [1;32mas[0m [0msns[0m[1;33m[0m[1;33m[0m[0m
[0;32m      6[0m [1;32mimport[0m [0mxlwings[0m [1;32mas[0m [0mxw[0m[1;33m[0m[1;33m[0m[0m
[1;32m----> 7[1;33m [1;32mimport[0m [0mresearchtools[0m[1;33m.[0m[0mapi[0m [1;32mas[0m [0mrt[0m[1;33m[0m[1;33m[0m[0m
[0m[0;32m      8[0m [0mplt[0m[1;33m.[0m[0mstyle[0m[1;33m.[0m[0muse[0m[1;33m([0m[1;34m'ggplot'[0m[1;33m)[0m[1;33m[0m[1;33m[0m[0m
[0;32m      9[0m [0mplt[0m[1;33m.[0m[0mrcParams[0m[1;33m[[0m[1;34m'figure.figsize'[0m[1;33m][0m [1;33m=[0m [1;33m[[0m[1;36m14[0m[1;33m,[0m [1;36m8[0m[1;33m][0m[1;33m[0m[1;33m[0m[0m

[1;31mModuleNotFoundError[0m: No module named 'researchtools'
ModuleNotFoundError: No module named 'researchtools'

